Workbook

Sheet LIBERACION
G1: 1500 | H1: 1000 | I1: 500 | J1: 300 | K1: 250 | L1: 200 | M1: 150 | N1: 100 | O1: 75 | P1: 50 | Q1: 100 | R1: 50 | S1: 25 | T1: 10 | W1: =SUM(V:V) -> 3328220
A2: Timestamp | B2: TURNO | C2: OPERADOR | D2: PRODUCTO | E2: CALIBRE | F2: COLOR DEL PRODUCTO | G2: BOBINAS (1500m) | H2: BOBINAS (1000m) | I2: BOBINAS (500m) | J2: BOBINAS (300m) | K2: BOBINAS (250m) | L2: BOBINAS (200m) | M2: BOBINAS (150m) | N2: BOBINAS (100 m) | O2: BOBINAS (75m) | P2: BOBINAS (50 m) | Q2: ROLLO (100m) | R2: Tramos (50m) | S2: Tramos (25m) | T2: Tramos (10m) | U2: EXTENSIONES (3m-5m-10m) - CANTIDAD | V2: METROS | W2: PAIS [X] | X2: LOTE | Y2: FECHA
A3: 46174.334 | B3: N | C3: LUIS S, FREDDY CH | D3: CABLE THHW 7H | E3: 12 | F3: ROJO | Q3: 400 | V3: =SUMPRODUCT(G3:T3,$G$1:$T$1) -> 40000 | W3: COLOMBIA | X3: N/A | Y3: 46174
A4: 46174.336 | B4: N | C4: LUIS S, FREDDY CH | D4: CABLE THHW 7H | E4: 12 | F4: NEGRO | Q4: 400 | V4: =SUMPRODUCT(G4:T4,$G$1:$T$1) -> 40000 | W4: COLOMBIA | X4: N/A | Y4: 46174
A5: 46174.337 | B5: M | C5: JOEL S, JESSICA V | D5: GEMELO SPT | E5: 2X18 | F5: BLANCO | Q5: 185 | V5: =SUMPRODUCT(G5:T5,$G$1:$T$1) -> 18500 | W5: ECUADOR | X5: N/A | Y5: 46174
A6: 46174.339 | B6: M | C6: JOEL S, JESSICA V | D6: CABLE THHW 7H | E6: 12 | F6: NEGRO | Q6: 366 | V6: =SUMPRODUCT(G6:T6,$G$1:$T$1) -> 36600 | W6: COLOMBIA | X6: N/A | Y6: 46174
A7: 46174.34 | B7: M | C7: JOEL S, JESSICA V | D7: CABLE THHW 7H | E7: 12 | F7: ROJO | Q7: 400 | V7: =SUMPRODUCT(G7:T7,$G$1:$T$1) -> 40000 | W7: COLOMBIA | X7: N/A | Y7: 46174
A8: 46174.341 | B8: M | C8: JOEL S, JESSICA V | D8: CABLE THHW 7H | E8: 8 | F8: ROJO | I8: 5 | Q8: 41 | V8: =SUMPRODUCT(G8:T8,$G$1:$T$1) -> 6600 | W8: COLOMBIA | X8: N/A | Y8: 46174
A9: 46174.342 | B9: M | C9: JOEL S, JESSICA V | D9: CABLE THHW 7H | E9: 8 | F9: VERDE | Q9: 13 | S9: 4 | V9: =SUMPRODUCT(G9:T9,$G$1:$T$1) -> 1400 | W9: COLOMBIA | X9: N/A | Y9: 46174
A10: 46174.342 | B10: M | C10: JOEL S, JESSICA V | D10: CABLE THHW 7H | E10: 8 | F10: AZUL | I10: 8 | Q10: 8 | S10: 6 | V10: =SUMPRODUCT(G10:T10,$G$1:$T$1) -> 4950 | W10: COLOMBIA | X10: N/A | Y10: 46174
A11: 46174.343 | B11: M | C11: JOEL S, JESSICA V | D11: CABLE THHW 7H | E11: 8 | F11: NEGRO | I11: 14 | S11: 4 | V11: =SUMPRODUCT(G11:T11,$G$1:$T$1) -> 7100 | W11: COLOMBIA | X11: N/A | Y11: 46174
A12: 46174.344 | B12: M | C12: JOEL S, JUAN DIEGO S, JESSICA V | D12: CABLE THHW 7H | E12: 12 | F12: AZUL | Q12: 35 | V12: =SUMPRODUCT(G12:T12,$G$1:$T$1) -> 3500 | W12: COLOMBIA | X12: N/A | Y12: 46174
A13: 46174.345 | B13: M | C13: DIEGO Z, JESSICA V | D13: CABLE THHW 7H | E13: 8 | F13: BLANCO | I13: 20 | V13: =SUMPRODUCT(G13:T13,$G$1:$T$1) -> 10000 | W13: COLOMBIA | X13: N/A | Y13: 46174
A14: 46174.35 | B14: M | C14: JOEL S, JESSICA V | D14: GEMELO SPT | E14: 2X16 | F14: BLANCO | Q14: 219 | V14: =SUMPRODUCT(G14:T14,$G$1:$T$1) -> 21900 | W14: ECUADOR | X14: N/A | Y14: 46174
A15: 46174.351 | B15: M | C15: JOEL S, JESSICA V | D15: CABLE THHW 7H | E15: 12 | F15: BLANCO | Q15: 173 | S15: 11 | V15: =SUMPRODUCT(G15:T15,$G$1:$T$1) -> 17575 | W15: COLOMBIA | X15: N/A | Y15: 46174
A16: 46174.353 | B16: N | C16: LUIS S, FREDDY CH | D16: CABLE THHW 7H | E16: 12 | F16: NEGRO | Q16: 251 | S16: 5 | V16: =SUMPRODUCT(G16:T16,$G$1:$T$1) -> 25225 | W16: COLOMBIA | X16: N/A | Y16: 46174
A17: 46174.355 | B17: N | C17: LUIS S, FREDDY CH | D17: GEMELO SPT | E17: 2X16 | F17: BLANCO | Q17: 128 | V17: =SUMPRODUCT(G17:T17,$G$1:$T$1) -> 12800 | W17: ECUADOR | X17: N/A | Y17: 46174
A18: 46174.356 | B18: N | C18: LUIS S, FREDDY CH | D18: GEMELO SPT | E18: 2X18 | F18: BLANCO | Q18: 35 | S18: 7 | V18: =SUMPRODUCT(G18:T18,$G$1:$T$1) -> 3675 | W18: ECUADOR | X18: N/A | Y18: 46174
A19: 46174.358 | B19: M | C19: DIEGO Z, JESSICA V | D19: GEMELO SPT | E19: 2X10 | F19: BLANCO | K19: 8 | S19: 4 | V19: =SUMPRODUCT(G19:T19,$G$1:$T$1) -> 2100 | W19: ECUADOR | X19: N/A | Y19: 46174
A20: 46174.359 | B20: M | C20: DIEGO Z, JESSICA V | D20: CABLE THHW 7H | E20: 12 | F20: ROJO | I20: 10 | V20: =SUMPRODUCT(G20:T20,$G$1:$T$1) -> 5000 | W20: COLOMBIA | X20: N/A | Y20: 46174
A21: 46174.359 | B21: M | C21: DIEGO Z, JESSICA V | D21: CABLE THHW 7H | E21: 12 | F21: AMARIILO | I21: 15 | V21: =SUMPRODUCT(G21:T21,$G$1:$T$1) -> 7500 | W21: COLOMBIA | X21: N/A | Y21: 46174
A22: 46174.36 | B22: M | C22: DIEGO Z, JESSICA V | D22: CABLE THHW 7H | E22: 12 | F22: AZUL | I22: 25 | V22: =SUMPRODUCT(G22:T22,$G$1:$T$1) -> 12500 | W22: COLOMBIA | X22: N/A | Y22: 46174
A23: 46174.361 | B23: M | C23: JOEL S, JESSICA V | D23: CABLE THHW 7H | E23: 12 | F23: ROJO | Q23: 258 | S23: 13 | V23: =SUMPRODUCT(G23:T23,$G$1:$T$1) -> 26125 | W23: COLOMBIA | X23: N/A | Y23: 46174
A24: 46174.363 | B24: N | C24: LUIS S, FREDDY CH | D24: CABLE THHW 7H | E24: 12 | F24: ROJO | Q24: 196 | V24: =SUMPRODUCT(G24:T24,$G$1:$T$1) -> 19600 | W24: COLOMBIA | X24: N/A | Y24: 46174
A25: 46174.364 | B25: N | C25: JUAN DIEGO S, FREDDY CH | D25: GEMELO SPT | E25: 2X12 | F25: BLANCO | Q25: 12 | S25: 7 | V25: =SUMPRODUCT(G25:T25,$G$1:$T$1) -> 1375 | W25: ECUADOR | X25: N/A | Y25: 46174
A26: 46174.368 | B26: M | C26: LUIS S, JESSICA V | D26: CABLE THHW 7H | E26: 12 | F26: VERDE | Q26: 4 | S26: 6 | V26: =SUMPRODUCT(G26:T26,$G$1:$T$1) -> 550 | W26: COLOMBIA | X26: N/A | Y26: 46174
A27: 46174.368 | B27: M | C27: LUIS S, FREDDY CH | D27: CABLE THHW 7H | E27: 12 | F27: AMARIILO | S27: 8 | V27: =SUMPRODUCT(G27:T27,$G$1:$T$1) -> 200 | W27: COLOMBIA | X27: N/A | Y27: 46174
A28: 46174.369 | B28: M | C28: JOEL S, JESSICA V | D28: CABLE THHW 7H | E28: 10 | F28: ROJO | Q28: 2 | S28: 4 | V28: =SUMPRODUCT(G28:T28,$G$1:$T$1) -> 300 | W28: COLOMBIA | X28: N/A | Y28: 46174
A29: 46174.369 | B29: M | C29: JOEL S, JESSICA V | D29: CABLE THHW 7H | E29: 10 | F29: VERDE | S29: 5 | V29: =SUMPRODUCT(G29:T29,$G$1:$T$1) -> 125 | W29: COLOMBIA | X29: N/A | Y29: 46174
A30: 46175.332 | B30: N | C30: JOEL S, FREDDY CH | D30: HALOGENO HFFR | E30: 14 | F30: ROJO | Q30: 123 | S30: 1 | V30: =SUMPRODUCT(G30:T30,$G$1:$T$1) -> 12325 | W30: COLOMBIA | X30: 2606H01 | Y30: 46175
A31: 46175.333 | B31: N | C31: JOEL S, FREDDY CH | D31: HALOGENO HFFR | E31: 14 | F31: NEGRO | Q31: 118 | S31: 3 | V31: =SUMPRODUCT(G31:T31,$G$1:$T$1) -> 11875 | W31: COLOMBIA | X31: 2606H01 | Y31: 46175
A32: 46175.334 | B32: M | C32: LUIS S, JESSICA V | D32: GEMELO SPT | E32: 2X14 | F32: BLANCO | Q32: 54 | S32: 3 | V32: =SUMPRODUCT(G32:T32,$G$1:$T$1) -> 5475 | W32: ECUADOR | X32: 2606G01 | Y32: 46175
A33: 46175.335 | B33: N | C33: JOEL S, FREDDY CH | D33: GEMELO SPT | E33: 2X14 | F33: BLANCO | Q33: 156 | V33: =SUMPRODUCT(G33:T33,$G$1:$T$1) -> 15600 | W33: ECUADOR | X33: 2606G01 | Y33: 46175
A34: 46175.337 | B34: N | C34: JOEL S, FREDDY CH | D34: CABLE THHW 7H | E34: 10 | F34: NEGRO | Q34: 106 | S34: 3 | V34: =SUMPRODUCT(G34:T34,$G$1:$T$1) -> 10675 | W34: COLOMBIA | X34: N/A | Y34: 46175
A35: 46175.338 | B35: M | C35: LUIS S, JESSICA V | D35: CABLE THHW 7H | E35: 10 | F35: NEGRO | Q35: 24 | V35: =SUMPRODUCT(G35:T35,$G$1:$T$1) -> 2400 | W35: COLOMBIA | X35: N/A | Y35: 46175
A36: 46175.339 | B36: M | C36: LUIS S, FREDDY CH | D36: CABLE THHW 7H | E36: 10 | F36: NEGRO | Q36: 79 | V36: =SUMPRODUCT(G36:T36,$G$1:$T$1) -> 7900 | W36: COLOMBIA | X36: N/A | Y36: 46175
A37: 46175.34 | B37: M | C37: LUIS S, JESSICA V | D37: CABLE THHW 7H | E37: 12 | F37: ROJO | Q37: 152 | V37: =SUMPRODUCT(G37:T37,$G$1:$T$1) -> 15200 | W37: COLOMBIA | X37: N/A | Y37: 46175
A38: 46175.341 | B38: M | C38: LUIS S, JESSICA V | D38: CABLE THHW 7H | E38: 12 | F38: BLANCO | Q38: 81 | V38: =SUMPRODUCT(G38:T38,$G$1:$T$1) -> 8100 | W38: COLOMBIA | X38: N/A | Y38: 46175
A39: 46175.342 | B39: M | C39: DIEGO Z, JESSICA V | D39: CONCENTRICO TC | E39: 3X14 | F39: NEGRO | Q39: 22 | V39: =SUMPRODUCT(G39:T39,$G$1:$T$1) -> 2200 | W39: ECUADOR | X39: N/A | Y39: 46175
A40: 46175.342 | B40: M | C40: DIEGO Z, JESSICA V | D40: GEMELO SPT | E40: 2X10 | F40: BLANCO | K40: 4 | V40: =SUMPRODUCT(G40:T40,$G$1:$T$1) -> 1000 | W40: ECUADOR | X40: N/A | Y40: 46175
...

Sheet OP
D1: CONTROL DE DESPERDICIO | F1: Código: | G1: R-CC-29
F2: Fecha de revisión: | G2: 25-08-28
F3: N° de versión: | G3: 3
B5: FEBRERO
A6: FAMILIA | B6: OP/OT/OI/OC/OTRO | C6: LOTE | D6: DESCRIPCION | E6: CALIBRE | F6: PESO TOTAL | G6: PRODUCCION METROS
A7: FLEX HFFR | B7: OP | C7: 2606H01 | D7: HALOGENO HFFR | E7: 14 | F7: 6.72 | G7: =SUMIFS(LIBERACION!$V:$V,LIBERACION!$D:$D,D7,LIBERACION!$E:$E,E7,LIBERACION!$X:$X,C7) -> 178500
A8: FLEX HFFR | B8: OP | C8: 2606H02 | D8: HALOGENO HFFR | E8: 12 | F8: 14.22 | G8: =SUMIFS(LIBERACION!$V:$V,LIBERACION!$D:$D,D8,LIBERACION!$E:$E,E8,LIBERACION!$X:$X,C8) -> 104150
A9: FLEX THHW | B9: OP | C9: 2606F01 | D9: CABLE THHW 7H | E9: 12 | F9: 1.59 | G9: =SUMIFS(LIBERACION!$V:$V,LIBERACION!$D:$D,D9,LIBERACION!$E:$E,E9,LIBERACION!$X:$X,C9) -> 2125
A10: FLEX THHW | B10: OP | C10: 2606F02 | D10: CABLE THHW 7H | E10: 8 | F10: 96.11 | G10: =SUMIFS(LIBERACION!$V:$V,LIBERACION!$D:$D,D10,LIBERACION!$E:$E,E10,LIBERACION!$X:$X,C10) -> 37250
A11: FLEX THHW | B11: OP | C11: 2606F03 | D11: CABLE THHW 7H | E11: 10 | F11: 0 | G11: =SUMIFS(LIBERACION!$V:$V,LIBERACION!$D:$D,D11,LIBERACION!$E:$E,E11,LIBERACION!$X:$X,C11) -> 725
A12: FLEX THHW | B12: OP | C12: 2606F04 | D12: CABLE THHW 7H | E12: 10 | F12: 1.38 | G12: =SUMIFS(LIBERACION!$V:$V,LIBERACION!$D:$D,D12,LIBERACION!$E:$E,E12,LIBERACION!$X:$X,C12) -> 15050
A13: FLEX THHW | B13: OP | C13: 2606F05 | D13: CABLE THHW 7H | E13: 12 | F13: 20.46 | G13: =SUMIFS(LIBERACION!$V:$V,LIBERACION!$D:$D,D13,LIBERACION!$E:$E,E13,LIBERACION!$X:$X,C13) -> 124375
A14: FLEX THHW | B14: OP | C14: 2606F06 | D14: FLEXIBLE THHW PLUS | E14: 12 | F14: 8.4 | G14: =SUMIFS(LIBERACION!$V:$V,LIBERACION!$D:$D,D14,LIBERACION!$E:$E,E14,LIBERACION!$X:$X,C14) -> 7300
A15: FLEX THHW | B15: OP | C15: 2606F07 | D15: FLEXIBLE TFF | E15: 16 | F15: 2.67 | G15: =SUMIFS(LIBERACION!$V:$V,LIBERACION!$D:$D,D15,LIBERACION!$E:$E,E15,LIBERACION!$X:$X,C15) -> 3050
A16: FLEX THHW | B16: OP | C16: 2606F08 | D16: FLEXIBLE THHW PLUS | E16: 12 | F16: 67.87 | G16: =SUMIFS(LIBERACION!$V:$V,LIBERACION!$D:$D,D16,LIBERACION!$E:$E,E16,LIBERACION!$X:$X,C16) -> 640725
A17: FLEX THHW | B17: OP | C17: 2606F09 | D17: FLEXIBLE THHW PLUS | E17: 14 | F17: 0.94 | G17: =SUMIFS(LIBERACION!$V:$V,LIBERACION!$D:$D,D17,LIBERACION!$E:$E,E17,LIBERACION!$X:$X,C17) -> 1800
A18: FLEX THHW | B18: OP | C18: 2606F10 | D18: FLEXIBLE TFF | E18: 16 | F18: 4.63 | G18: =SUMIFS(LIBERACION!$V:$V,LIBERACION!$D:$D,D18,LIBERACION!$E:$E,E18,LIBERACION!$X:$X,C18) -> 59500
... A23: FLEX THHW | B23: OP | C23: 2606F15 | D23: FLEXIBLE THHW PLUS | E23: 6 | F23: 8.55 | G23: =SUMIFS(LIBERACION!$V:$V,LIBERACION!$D:$D,D23,LIBERACION!$E:$E,E23,LIBERACION!$X:$X,C23) -> 6225
A24: FLEX THHW | B24: OP | F24: 0 | G24: =SUMIFS(LIBERACION!$V:$V,LIBERACION!$D:$D,D24,LIBERACION!$E:$E,E24,LIBERACION!$X:$X,C24) -> 0
A25: FLEX THHW | B25: OP | F25: 0 | G25: =SUMIFS(LIBERACION!$V:$V,LIBERACION!$D:$D,D25,LIBERACION!$E:$E,E25,LIBERACION!$X:$X,C25) -> 0
A26: FLEX THHW | B26: OP | F26: 0 | G26: =SUMIFS(LIBERACION!$V:$V,LIBERACION!$D:$D,D26,LIBERACION!$E:$E,E26,LIBERACION!$X:$X,C26) -> 0
A27: MULT-CC | B27: OP | C27: 2606M01 | D27: MULTICONDUCTOR TC | E27: 2X12 | F27: 2.7 | G27: =SUMIFS(LIBERACION!$V:$V,LIBERACION!$D:$D,D27,LIBERACION!$E:$E,E27,LIBERACION!$X:$X,C27) -> 10100
A28: MULT-CC | B28: OP | C28: 2606M02 | D28: MULTICONDUCTOR TC | E28: 3X12 | F28: 17.82 | G28: =SUMIFS(LIBERACION!$V:$V,LIBERACION!$D:$D,D28,LIBERACION!$E:$E,E28,LIBERACION!$X:$X,C28) -> 14725
A29: MULT-CC | B29: OP | C29: 2606M03 | D29: MULTICONDUCTOR TC | E29: 3X10 | F29: 0 | G29: =SUMIFS(LIBERACION!$V:$V,LIBERACION!$D:$D,D29,LIBERACION!$E:$E,E29,LIBERACION!$X:$X,C29) -> 3100
A30: MULT-CC | B30: OP | C30: 2606M04 | D30: CONCENTRICO TC | E30: 2X12 | F30: 19.36 | G30: =SUMIFS(LIBERACION!$V:$V,LIBERACION!$D:$D,D30,LIBERACION!$E:$E,E30,LIBERACION!$X:$X,C30) -> 29125
A31: MULT-CC | B31: OP | C31: 2606M05 | D31: CONCENTRICO TC | E31: 3X12 | F31: 48.47 | G31: =SUMIFS(LIBERACION!$V:$V,LIBERACION!$D:$D,D31,LIBERACION!$E:$E,E31,LIBERACION!$X:$X,C31) -> 24650
A32: MULT-CC | B32: OP | C32: 2606M06 | D32: CONCENTRICO TC | E32: 2X16 | F32: 31.68 | G32: =SUMIFS(LIBERACION!$V:$V,LIBERACION!$D:$D,D32,LIBERACION!$E:$E,E32,LIBERACION!$X:$X,C32) -> 12725
A33: MULT-CC | B33: OP | C33: 2606M07 | D33: CONCENTRICO TC | E33: 2X14 | F33: 38.8 | G33: =SUMIFS(LIBERACION!$V:$V,LIBERACION!$D:$D,D33,LIBERACION!$E:$E,E33,LIBERACION!$X:$X,C33) -> 25275
A34: MULT-CC | B34: OP | C34: 2606M08 | D34: CONCENTRICO TC | E34: 3X14 | F34: 2.41 | G34: =SUMIFS(LIBERACION!$V:$V,LIBERACION!$D:$D,D34,LIBERACION!$E:$E,E34,LIBERACION!$X:$X,C34) -> 15025
A35: MULT-CC | B35: OP | C35: 2606M09 | D35: CONCENTRICO TC | E35: 2X10 | F35: 3.32 | G35: =SUMIFS(LIBERACION!$V:$V,LIBERACION!$D:$D,D35,LIBERACION!$E:$E,E35,LIBERACION!$X:$X,C35) -> 10175
A36: MULT-CC | B36: OP | C36: 2606M10 | D36: CONCENTRICO TC | E36: 3X10 | F36: 29.43 | G36: =SUMIFS(LIBERACION!$V:$V,LIBERACION!$D:$D,D36,LIBERACION!$E:$E,E36,LIBERACION!$X:$X,C36) -> 9850
A37: MULT-CC | B37: OP | C37: 2606M11 | D37: CONCENTRICO TC | E37: 3X8 | F37: 16.99 | G37: =SUMIFS(LIBERACION!$V:$V,LIBERACION!$D:$D,D37,LIBERACION!$E:$E,E37,LIBERACION!$X:$X,C37) -> 4975
A38: MULT-CC | B38: OP | C38: 2606M12 | D38: CONCENTRICO TC | E38: 2X14 | F38: 0 | G38: =SUMIFS(LIBERACION!$V:$V,LIBERACION!$D:$D,D38,LIBERACION!$E:$E,E38,LIBERACION!$X:$X,C38) -> 100
A39: MULT-CC | B39: OP | C39: 2606M13 | D39: MULTICONDUCTOR TC | E39: 2X16 | F39: 0 | G39: =SUMIFS(LIBERACION!$V:$V,LIBERACION!$D:$D,D39,LIBERACION!$E:$E,E39,LIBERACION!$X:$X,C39) -> 9500
A40: MULT-CC | B40: OP | C40: 2606M14 | D40: CONCENTRICO TC | F40: 0 | G40: =SUMIFS(LIBERACION!$V:$V,LIBERACION!$D:$D,D40,LIBERACION!$E:$E,E40,LIBERACION!$X:$X,C40) -> 0
A41: GEM-SPT | B41: OP | C41: 2606G01 | D41: GEMELO SPT | E41: 2X14 | F41: 45.94 | G41: =SUMIFS(LIBERACION!$V:$V,LIBERACION!$D:$D,D41,LIBERACION!$E:$E,E41,LIBERACION!$X:$X,C41) -> 241060
A42: GEM-SPT | B42: OP | C42: 2606G02 | D42: GEMELO SPT | E42: 2X16 | F42: 29.83 | G42: =SUMIFS(LIBERACION!$V:$V,LIBERACION!$D:$D,D42,LIBERACION!$E:$E,E42,LIBERACION!$X:$X,C42) -> 179260
A43: GEM-SPT | B43: OP | C43: 2606G03 | D43: GEMELO SPT | E43: 2X12 | F43: 59.84 | G43: =SUMIFS(LIBERACION!$V:$V,LIBERACION!$D:$D,D43,LIBERACION!$E:$E,E43,LIBERACION!$X:$X,C43) -> 162800
A44: GEM-SPT | B44: OP | C44: 2606G04 | D44: GEMELO SPT | E44: 2X20 | F44: 14.8 | G44: =SUMIFS(LIBERACION!$V:$V,LIBERACION!$D:$D,D44,LIBERACION!$E:$E,E44,LIBERACION!$X:$X,C44) -> 80075
A45: GEM-SPT | B45: OP | C45: 2606G05 | D45: GEMELO SPT | E45: 2X10 | F45: 28.72 | G45: =SUMIFS(LIBERACION!$V:$V,LIBERACION!$D:$D,D45,LIBERACION!$E:$E,E45,LIBERACION!$X:$X,C45) -> 47350
...

Sheet ANALISIS
B2: ANÁLISIS DESPERDICCIO - JUNIO2026
B3: FAMILIA | C3: CALIBRE | D3: METROS PRODUCIDOS | E3: ESTANDAR g | F3: PRODUCCIÓN kg | G3: DESPERDICIO kg | H3: PORCENTAJE DE DESPERDICIO | I3: OBSERVACIONES | J3: DESPERDICIO metros
B4: FLEX THHW | C4: 16 | D4: =SUMIFS(OP!G:G,OP!A:A,B4,OP!E:E,C4) -> 62550 | E4: 17.3 | F4: =(D4*E4)/1000 -> 1082.115 | G4: =SUMIFS(OP!F:F,OP!A:A,B4,OP!E:E,C4) -> 7.3 | H4: =G4/(F4+G4) -> 0.006700844 | J4: =(G4)/(E4/1000) -> 421.96532
B5: FLEX THHW | C5: 14 | D5: =SUMIFS(OP!G:G,OP!A:A,B5,OP!E:E,C5) -> 480075 | E5: 11.972 | F5: =(D5*E5)/1000 -> 5747.4579 | G5: =SUMIFS(OP!F:F,OP!A:A,B5,OP!E:E,C5) -> 28.15 | H5: =G5/(F5+G5) -> 0.0048739458 | J5: =(G5)/(E5/1000) -> 2351.3197
B6: FLEX THHW | C6: 12 | D6: =SUMIFS(OP!G:G,OP!A:A,B6,OP!E:E,C6) -> 774525 | E6: 23.819 | F6: =(D6*E6)/1000 -> 18448.411 | G6: =SUMIFS(OP!F:F,OP!A:A,B6,OP!E:E,C6) -> 98.32 | H6: =G6/(F6+G6) -> 0.0053012038 | J6: =(G6)/(E6/1000) -> 4127.7971
B7: FLEX THHW | C7: 10 | D7: =SUMIFS(OP!G:G,OP!A:A,B7,OP!E:E,C7) -> 136550 | E7: 35.51 | F7: =(D7*E7)/1000 -> 4848.8905 | G7: =SUMIFS(OP!F:F,OP!A:A,B7,OP!E:E,C7) -> 22.08 | H7: =G7/(F7+G7) -> 0.0045329776 | J7: =(G7)/(E7/1000) -> 621.79668
B8: FLEX THHW | C8: 8 | D8: =SUMIFS(OP!G:G,OP!A:A,B8,OP!E:E,C8) -> 38600 | E8: 58.328 | F8: =(D8*E8)/1000 -> 2251.4608 | G8: =SUMIFS(OP!F:F,OP!A:A,B8,OP!E:E,C8) -> 99.13 | H8: =G8/(F8+G8) -> 0.042172376 | I8: BOBINA TRENZADA CON CORTE | J8: =(G8)/(E8/1000) -> 1699.5268
B9: FLEX THHW | C9: 6 | D9: =SUMIFS(OP!G:G,OP!A:A,B9,OP!E:E,C9) -> 6225 | E9: 86.886 | F9: =(D9*E9)/1000 -> 540.86535 | G9: =SUMIFS(OP!F:F,OP!A:A,B9,OP!E:E,C9) -> 8.55 | H9: =G9/(F9+G9) -> 0.015561997 | J9: =(G9)/(E9/1000) -> 98.404806
B10: FLEX HFFR | C10: 12 | D10: =SUMIFS(OP!G:G,OP!A:A,B10,OP!E:E,C10) -> 104150 | E10: 22.07 | F10: =(D10*E10)/1000 -> 2298.5905 | G10: =SUMIFS(OP!F:F,OP!A:A,B10,OP!E:E,C10) -> 14.22 | H10: =G10/(F10+G10) -> 0.0061483636 | J10: =(G10)/(E10/1000) -> 644.31355
B11: FLEX HFFR | C11: 14 | D11: =SUMIFS(OP!G:G,OP!A:A,B11,OP!E:E,C11) -> 178500 | E11: 17.37 | F11: =(D11*E11)/1000 -> 3100.545 | G11: =SUMIFS(OP!F:F,OP!A:A,B11,OP!E:E,C11) -> 6.72 | H11: =G11/(F11+G11) -> 0.0021626736 | J11: =(G11)/(E11/1000) -> 386.87392
B12: MULT-CC | C12: 3X12 | D12: =SUMIFS(OP!G:G,OP!A:A,B12,OP!E:E,C12) -> 39375 | E12: 149.34 | F12: =(D12*E12)/1000 -> 5880.2625 | G12: =SUMIFS(OP!F:F,OP!A:A,B12,OP!E:E,C12) -> 66.29 | H12: =G12/(F12+G12) -> 0.011147636 | J12: =(G12)/(E12/1000) -> 443.88643
B13: MULT-CC | C13: 2X12 | D13: =SUMIFS(OP!G:G,OP!A:A,B13,OP!E:E,C13) -> 39225 | E13: 114.02 | F13: =(D13*E13)/1000 -> 4472.4345 | G13: =SUMIFS(OP!F:F,OP!A:A,B13,OP!E:E,C13) -> 22.06 | H13: =G13/(F13+G13) -> 0.0049082272 | J13: =(G13)/(E13/1000) -> 193.47483
B14: MULT-CC | C14: 3X8 | D14: =SUMIFS(OP!G:G,OP!A:A,B14,OP!E:E,C14) -> 4975 | E14: 405.875 | F14: =(D14*E14)/1000 -> 2019.2281 | G14: =SUMIFS(OP!F:F,OP!A:A,B14,OP!E:E,C14) -> 16.99 | H14: =G14/(F14+G14) -> 0.0083438998 | J14: =(G14)/(E14/1000) -> 41.860179
B15: MULT-CC | C15: 2X14 | D15: =SUMIFS(OP!G:G,OP!A:A,B15,OP!E:E,C15) -> 25375 | E15: 63.552 | F15: =(D15*E15)/1000 -> 1612.632 | G15: =SUMIFS(OP!F:F,OP!A:A,B15,OP!E:E,C15) -> 38.8 | H15: =G15/(F15+G15) -> 0.023494761 | I15: DESPERDICIO CCAA TRENZADO | J15: =(G15)/(E15/1000) -> 610.52367
B16: MULT-CC | C16: 3X14 | D16: =SUMIFS(OP!G:G,OP!A:A,B16,OP!E:E,C16) -> 15025 | E16: 106.045 | F16: =(D16*E16)/1000 -> 1593.3261 | G16: =SUMIFS(OP!F:F,OP!A:A,B16,OP!E:E,C16) -> 2.41 | H16: =G16/(F16+G16) -> 0.0015102748 | J16: =(G16)/(E16/1000) -> 22.726201
B17: MULT-CC | C17: 2X16 | D17: =SUMIFS(OP!G:G,OP!A:A,B17,OP!E:E,C17) -> 22225 | E17: 62.16 | F17: =(D17*E17)/1000 -> 1381.506 | G17: =SUMIFS(OP!F:F,OP!A:A,B17,OP!E:E,C17) -> 31.68 | H17: =G17/(F17+G17) -> 0.022417431 | I17: DESPERDICIO CCAA TRENZADO | J17: =(G17)/(E17/1000) -> 509.65251
B18: MULT-CC | C18: 3X10 | D18: =SUMIFS(OP!G:G,OP!A:A,B18,OP!E:E,C18) -> 12950 | E18: 238.65 | F18: =(D18*E18)/1000 -> 3090.5175 | G18: =SUMIFS(OP!F:F,OP!A:A,B18,OP!E:E,C18) -> 29.43 | H18: =G18/(F18+G18) -> 0.009432851 | J18: =(G18)/(E18/1000) -> 123.31867
B19: MULT-CC | C19: 2X10 | D19: =SUMIFS(OP!G:G,OP!A:A,B19,OP!E:E,C19) -> 10175 | E19: 189.045 | F19: =(D19*E19)/1000 -> 1923.5329 | G19: =SUMIFS(OP!F:F,OP!A:A,B19,OP!E:E,C19) -> 3.32 | H19: =G19/(F19+G19) -> 0.0017230169 | J19: =(G19)/(E19/1000) -> 17.561956
B20: GEM-SPT | C20: 2X16 | D20: =SUMIFS(OP!G:G,OP!A:A,B20,OP!E:E,C20) -> 179260 | E20: 36.83 | F20: =(D20*E20)/1000 -> 6602.1458 | G20: =SUMIFS(OP!F:F,OP!A:A,B20,OP!E:E,C20) -> 29.83 | H20: =G20/(F20+G20) -> 0.0044979054 | J20: =(G20)/(E20/1000) -> 809.93755
B21: GEM-SPT | C21: 2X14 | D21: =SUMIFS(OP!G:G,OP!A:A,B21,OP!E:E,C21) -> 241060 | E21: 45.987 | F21: =(D21*E21)/1000 -> 11085.626 | G21: =SUMIFS(OP!F:F,OP!A:A,B21,OP!E:E,C21) -> 45.94 | H21: =G21/(F21+G21) -> 0.0041270024 | J21: =(G21)/(E21/1000) -> 998.97797
B22: GEM-SPT | C22: 2X12 | D22: =SUMIFS(OP!G:G,OP!A:A,B22,OP!E:E,C22) -> 162800 | E22: 62.034 | F22: =(D22*E22)/1000 -> 10099.135 | G22: =SUMIFS(OP!F:F,OP!A:A,B22,OP!E:E,C22) -> 59.84 | H22: =G22/(F22+G22) -> 0.0058903579 | J22: =(G22)/(E22/1000) -> 964.6323
B23: GEM-SPT | C23: 2X10 | D23: =SUMIFS(OP!G:G,OP!A:A,B23,OP!E:E,C23) -> 47350 | E23: 76.18 | F23: =(D23*E23)/1000 -> 3607.123 | G23: =SUMIFS(OP!F:F,OP!A:A,B23,OP!E:E,C23) -> 28.72 | H23: =G23/(F23+G23) -> 0.007899131 | J23: =(G23)/(E23/1000) -> 377.00184
B24: GEM-SPT | C24: 2X18 | D24: =SUMIFS(OP!G:G,OP!A:A,B24,OP!E:E,C24) -> 125725 | E24: 26.185 | F24: =(D24*E24)/1000 -> 3292.1091 | G24: =SUMIFS(OP!F:F,OP!A:A,B24,OP!E:E,C24) -> 11.52 | H24: =G24/(F24+G24) -> 0.0034870742 | J24: =(G24)/(E24/1000) -> 439.94653
B25: GEM-SPT | C25: 2X20 | D25: =SUMIFS(OP!G:G,OP!A:A,B25,OP!E:E,C25) -> 80075 | E25: 14.402 | F25: =(D25*E25)/1000 -> 1153.2402 | G25: =SUMIFS(OP!F:F,OP!A:A,B25,OP!E:E,C25) -> 14.8 | H25: =G25/(F25+G25) -> 0.012670797 | J25: =(G25)/(E25/1000) -> 1027.6351
B26: TOTAL = | D26: =SUM(D4:D25) -> 2786770 | E26: =AVERAGE(E4:E25) -> 84.707273 | F26: =SUM(F4:F17) -> 55277.725 | G26: =SUM(G4:G17) -> 462.7 | H26: =G26/(F26+G26) -> 0.0083009772 | J26: =SUM(J4:J25) -> 16933.134

Sheet SEMANA 1
B1: }
B3: REPORTE DE LIBERACIÓN SEMANAL
B4: FECHA | C4: TURNO | F4: METROS POR DIA | G4: OBSERVACIONES
C5: MAÑANA | D5: TARDE | E5: NOCHE
C6: M | D6: T | E6: N
B7: 46174 | C7: =SUMIFS(LIBERACION!$V:$V,LIBERACION!$Y:$Y,$B7,LIBERACION!$B:$B,C$6) -> 222525 | D7: =SUMIFS(LIBERACION!$V:$V,LIBERACION!$Y:$Y,$B7,LIBERACION!$B:$B,D$6) -> 0 | E7: =SUMIFS(LIBERACION!$V:$V,LIBERACION!$Y:$Y,$B7,LIBERACION!$B:$B,E$6) -> 142675 | F7: =SUM(C7:E7) -> 365200
B8: 46175 | C8: =SUMIFS(LIBERACION!$V:$V,LIBERACION!$Y:$Y,$B8,LIBERACION!$B:$B,C$6) -> 62650 | D8: =SUMIFS(LIBERACION!$V:$V,LIBERACION!$Y:$Y,$B8,LIBERACION!$B:$B,D$6) -> 0 | E8: =SUMIFS(LIBERACION!$V:$V,LIBERACION!$Y:$Y,$B8,LIBERACION!$B:$B,E$6) -> 50475 | F8: =SUM(C8:E8) -> 113125
B9: 46176 | C9: =SUMIFS(LIBERACION!$V:$V,LIBERACION!$Y:$Y,$B9,LIBERACION!$B:$B,C$6) -> 68750 | D9: =SUMIFS(LIBERACION!$V:$V,LIBERACION!$Y:$Y,$B9,LIBERACION!$B:$B,D$6) -> 0 | E9: =SUMIFS(LIBERACION!$V:$V,LIBERACION!$Y:$Y,$B9,LIBERACION!$B:$B,E$6) -> 56000 | F9: =SUM(C9:E9) -> 124750
B10: 46177 | C10: =SUMIFS(LIBERACION!$V:$V,LIBERACION!$Y:$Y,$B10,LIBERACION!$B:$B,C$6) -> 64075 | D10: =SUMIFS(LIBERACION!$V:$V,LIBERACION!$Y:$Y,$B10,LIBERACION!$B:$B,D$6) -> 0 | E10: =SUMIFS(LIBERACION!$V:$V,LIBERACION!$Y:$Y,$B10,LIBERACION!$B:$B,E$6) -> 27900 | F10: =SUM(C10:E10) -> 91975 | G10: Argentina Halogenos 12 para presentación de 500
B11: 46178 | C11: =SUMIFS(LIBERACION!$V:$V,LIBERACION!$Y:$Y,$B11,LIBERACION!$B:$B,C$6) -> 43200 | D11: =SUMIFS(LIBERACION!$V:$V,LIBERACION!$Y:$Y,$B11,LIBERACION!$B:$B,D$6) -> 0 | E11: =SUMIFS(LIBERACION!$V:$V,LIBERACION!$Y:$Y,$B11,LIBERACION!$B:$B,E$6) -> 45700 | F11: =SUM(C11:E11) -> 88900 | G11: Tokio fabricación de flexibles 12 blanco, negro, verde para concéntricos Ecuador 75000 metros
E12: TOTAL | F12: =SUM( F7:F11 ) -> 783950
B16: REPORTE LIBERACIÓN PORCENTUAL %
B17: FECHA | C17: TURNO | F17: PORCENTAJE POR DIA
C18: MAÑANA | D18: TARDE | E18: NOCHE
C19: M | D19: T | E19: N
B20: =B7 -> 46174 | C20: =((C7*100)/500000)/100 -> 0.44505 | D20: =((D7*100)/500000)/100 -> 0 | E20: =((E7*100)/500000)/100 -> 0.28535 | F20: =SUM(C20:E20) -> 0.7304
B21: =B8 -> 46175 | C21: =((C8*100)/500000)/100 -> 0.1253 | D21: =((D8*100)/500000)/100 -> 0 | E21: =((E8*100)/500000)/100 -> 0.10095 | F21: =SUM(C21:E21) -> 0.22625
B22: =B9 -> 46176 | C22: =((C9*100)/500000)/100 -> 0.1375 | D22: =((D9*100)/500000)/100 -> 0 | E22: =((E9*100)/500000)/100 -> 0.112 | F22: =SUM(C22:E22) -> 0.2495
B23: =B10 -> 46177 | C23: =((C10*100)/500000)/100 -> 0.12815 | D23: =((D10*100)/500000)/100 -> 0 | E23: =((E10*100)/500000)/100 -> 0.0558 | F23: =SUM(C23:E23) -> 0.18395
B24: =B11 -> 46178 | C24: =((C11*100)/500000)/100 -> 0.0864 | D24: =((D11*100)/500000)/100 -> 0 | E24: =((E11*100)/500000)/100 -> 0.0914 | F24: =SUM(C24:E24) -> 0.1778
E25: TOTAL % | F25: =SUM(F20:F24) -> 1.5679

Sheet SEMANA 2
B1: }
B3: REPORTE DE LIBERACIÓN SEMANAL
B4: FECHA | C4: TURNO | F4: METROS POR DIA | G4: OBSERVACIONES
C5: MAÑANA | D5: TARDE | E5: NOCHE
C6: M | D6: T | E6: N
B7: 46181 | C7: =SUMIFS(LIBERACION!$V:$V,LIBERACION!$Y:$Y,$B7,LIBERACION!$B:$B,C$6) -> 128600 | D7: =SUMIFS(LIBERACION!$V:$V,LIBERACION!$Y:$Y,$B7,LIBERACION!$B:$B,D$6) -> 0 | E7: =SUMIFS(LIBERACION!$V:$V,LIBERACION!$Y:$Y,$B7,LIBERACION!$B:$B,E$6) -> 52900 | F7: =SUM(C7:E7) -> 181500
B8: 46182 | C8: =SUMIFS(LIBERACION!$V:$V,LIBERACION!$Y:$Y,$B8,LIBERACION!$B:$B,C$6) -> 88450 | D8: =SUMIFS(LIBERACION!$V:$V,LIBERACION!$Y:$Y,$B8,LIBERACION!$B:$B,D$6) -> 0 | E8: =SUMIFS(LIBERACION!$V:$V,LIBERACION!$Y:$Y,$B8,LIBERACION!$B:$B,E$6) -> 65900 | F8: =SUM(C8:E8) -> 154350
B9: 46183 | C9: =SUMIFS(LIBERACION!$V:$V,LIBERACION!$Y:$Y,$B9,LIBERACION!$B:$B,C$6) -> 89650 | D9: =SUMIFS(LIBERACION!$V:$V,LIBERACION!$Y:$Y,$B9,LIBERACION!$B:$B,D$6) -> 0 | E9: =SUMIFS(LIBERACION!$V:$V,LIBERACION!$Y:$Y,$B9,LIBERACION!$B:$B,E$6) -> 78475 | F9: =SUM(C9:E9) -> 168125
B10: 46184 | C10: =SUMIFS(LIBERACION!$V:$V,LIBERACION!$Y:$Y,$B10,LIBERACION!$B:$B,C$6) -> 119975 | D10: =SUMIFS(LIBERACION!$V:$V,LIBERACION!$Y:$Y,$B10,LIBERACION!$B:$B,D$6) -> 0 | E10: =SUMIFS(LIBERACION!$V:$V,LIBERACION!$Y:$Y,$B10,LIBERACION!$B:$B,E$6) -> 114275 | F10: =SUM(C10:E10) -> 234250
B11: 46185 | C11: =SUMIFS(LIBERACION!$V:$V,LIBERACION!$Y:$Y,$B11,LIBERACION!$B:$B,C$6) -> 146625 | D11: =SUMIFS(LIBERACION!$V:$V,LIBERACION!$Y:$Y,$B11,LIBERACION!$B:$B,D$6) -> 0 | E11: =SUMIFS(LIBERACION!$V:$V,LIBERACION!$Y:$Y,$B11,LIBERACION!$B:$B,E$6) -> 101100 | F11: =SUM(C11:E11) -> 247725
E12: TOTAL | F12: =SUM( F7:F11 ) -> 985950
B16: REPORTE LIBERACIÓN PORCENTUAL %
B17: FECHA | C17: TURNO | F17: PORCENTAJE POR DIA
C18: MAÑANA | D18: TARDE | E18: NOCHE
C19: M | D19: T | E19: N
B20: =B7 -> 46181 | C20: =((C7*100)/500000)/100 -> 0.2572 | D20: =((D7*100)/500000)/100 -> 0 | E20: =((E7*100)/500000)/100 -> 0.1058 | F20: =SUM(C20:E20) -> 0.363
B21: =B8 -> 46182 | C21: =((C8*100)/500000)/100 -> 0.1769 | D21: =((D8*100)/500000)/100 -> 0 | E21: =((E8*100)/500000)/100 -> 0.1318 | F21: =SUM(C21:E21) -> 0.3087
B22: =B9 -> 46183 | C22: =((C9*100)/500000)/100 -> 0.1793 | D22: =((D9*100)/500000)/100 -> 0 | E22: =((E9*100)/500000)/100 -> 0.15695 | F22: =SUM(C22:E22) -> 0.33625
B23: =B10 -> 46184 | C23: =((C10*100)/500000)/100 -> 0.23995 | D23: =((D10*100)/500000)/100 -> 0 | E23: =((E10*100)/500000)/100 -> 0.22855 | F23: =SUM(C23:E23) -> 0.4685
B24: =B11 -> 46185 | C24: =((C11*100)/500000)/100 -> 0.29325 | D24: =((D11*100)/500000)/100 -> 0 | E24: =((E11*100)/500000)/100 -> 0.2022 | F24: =SUM(C24:E24) -> 0.49545
E25: TOTAL % | F25: =SUM(F20:F24) -> 1.9719

Sheet SEMANA 3
B1: }
B3: REPORTE DE LIBERACIÓN SEMANAL
B4: FECHA | C4: TURNO | F4: METROS POR DIA | G4: OBSERVACIONES
C5: MAÑANA | D5: TARDE | E5: NOCHE
C6: M | D6: T | E6: N
B7: 46188 | C7: =SUMIFS(LIBERACION!$V:$V,LIBERACION!$Y:$Y,$B7,LIBERACION!$B:$B,C$6) -> 115775 | D7: =SUMIFS(LIBERACION!$V:$V,LIBERACION!$Y:$Y,$B7,LIBERACION!$B:$B,D$6) -> 0 | E7: =SUMIFS(LIBERACION!$V:$V,LIBERACION!$Y:$Y,$B7,LIBERACION!$B:$B,E$6) -> 65525 | F7: =SUM(C7:E7) -> 181300
B8: 46189 | C8: =SUMIFS(LIBERACION!$V:$V,LIBERACION!$Y:$Y,$B8,LIBERACION!$B:$B,C$6) -> 16375 | D8: =SUMIFS(LIBERACION!$V:$V,LIBERACION!$Y:$Y,$B8,LIBERACION!$B:$B,D$6) -> 0 | E8: =SUMIFS(LIBERACION!$V:$V,LIBERACION!$Y:$Y,$B8,LIBERACION!$B:$B,E$6) -> 94625 | F8: =SUM(C8:E8) -> 111000
B9: 46190 | C9: =SUMIFS(LIBERACION!$V:$V,LIBERACION!$Y:$Y,$B9,LIBERACION!$B:$B,C$6) -> 70725 | D9: =SUMIFS(LIBERACION!$V:$V,LIBERACION!$Y:$Y,$B9,LIBERACION!$B:$B,D$6) -> 0 | E9: =SUMIFS(LIBERACION!$V:$V,LIBERACION!$Y:$Y,$B9,LIBERACION!$B:$B,E$6) -> 45200 | F9: =SUM(C9:E9) -> 115925
B10: 46191 | C10: =SUMIFS(LIBERACION!$V:$V,LIBERACION!$Y:$Y,$B10,LIBERACION!$B:$B,C$6) -> 88975 | D10: =SUMIFS(LIBERACION!$V:$V,LIBERACION!$Y:$Y,$B10,LIBERACION!$B:$B,D$6) -> 0 | E10: =SUMIFS(LIBERACION!$V:$V,LIBERACION!$Y:$Y,$B10,LIBERACION!$B:$B,E$6) -> 65650 | F10: =SUM(C10:E10) -> 154625
B11: 46192 | C11: =SUMIFS(LIBERACION!$V:$V,LIBERACION!$Y:$Y,$B11,LIBERACION!$B:$B,C$6) -> 110175 | D11: =SUMIFS(LIBERACION!$V:$V,LIBERACION!$Y:$Y,$B11,LIBERACION!$B:$B,D$6) -> 0 | E11: =SUMIFS(LIBERACION!$V:$V,LIBERACION!$Y:$Y,$B11,LIBERACION!$B:$B,E$6) -> 136650 | F11: =SUM(C11:E11) -> 246825
E12: TOTAL | F12: =SUM( F7:F11 ) -> 809675
B16: REPORTE LIBERACIÓN PORCENTUAL %
B17: FECHA | C17: TURNO | F17: PORCENTAJE POR DIA
C18: MAÑANA | D18: TARDE | E18: NOCHE
C19: M | D19: T | E19: N
B20: =B7 -> 46188 | C20: =((C7*100)/500000)/100 -> 0.23155 | D20: =((D7*100)/500000)/100 -> 0 | E20: =((E7*100)/500000)/100 -> 0.13105 | F20: =SUM(C20:E20) -> 0.3626
B21: =B8 -> 46189 | C21: =((C8*100)/500000)/100 -> 0.03275 | D21: =((D8*100)/500000)/100 -> 0 | E21: =((E8*100)/500000)/100 -> 0.18925 | F21: =SUM(C21:E21) -> 0.222
B22: =B9 -> 46190 | C22: =((C9*100)/500000)/100 -> 0.14145 | D22: =((D9*100)/500000)/100 -> 0 | E22: =((E9*100)/500000)/100 -> 0.0904 | F22: =SUM(C22:E22) -> 0.23185
B23: =B10 -> 46191 | C23: =((C10*100)/500000)/100 -> 0.17795 | D23: =((D10*100)/500000)/100 -> 0 | E23: =((E10*100)/500000)/100 -> 0.1313 | F23: =SUM(C23:E23) -> 0.30925
B24: =B11 -> 46192 | C24: =((C11*100)/500000)/100 -> 0.22035 | D24: =((D11*100)/500000)/100 -> 0 | E24: =((E11*100)/500000)/100 -> 0.2733 | F24: =SUM(C24:E24) -> 0.49365
E25: TOTAL % | F25: =SUM(F20:F24) -> 1.61935

Sheet SEMANA 4
B1: }
B3: REPORTE DE LIBERACIÓN SEMANAL
B4: FECHA | C4: TURNO | F4: METROS POR DIA | G4: OBSERVACIONES
C5: MAÑANA | D5: TARDE | E5: NOCHE
C6: M | D6: T | E6: N
B7: 46195 | C7: =SUMIFS(LIBERACION!$V:$V,LIBERACION!$Y:$Y,$B7,LIBERACION!$B:$B,C$6) -> 60825 | D7: =SUMIFS(LIBERACION!$V:$V,LIBERACION!$Y:$Y,$B7,LIBERACION!$B:$B,D$6) -> 0 | E7: =SUMIFS(LIBERACION!$V:$V,LIBERACION!$Y:$Y,$B7,LIBERACION!$B:$B,E$6) -> 30000 | F7: =SUM(C7:E7) -> 90825 | G7: Argentina parada por mantenimiento
B8: 46196 | C8: =SUMIFS(LIBERACION!$V:$V,LIBERACION!$Y:$Y,$B8,LIBERACION!$B:$B,C$6) -> 49200 | D8: =SUMIFS(LIBERACION!$V:$V,LIBERACION!$Y:$Y,$B8,LIBERACION!$B:$B,D$6) -> 0 | E8: =SUMIFS(LIBERACION!$V:$V,LIBERACION!$Y:$Y,$B8,LIBERACION!$B:$B,E$6) -> 30250 | F8: =SUM(C8:E8) -> 79450 | G8: Argentina parada por mantenimiento
B9: 46197 | C9: =SUMIFS(LIBERACION!$V:$V,LIBERACION!$Y:$Y,$B9,LIBERACION!$B:$B,C$6) -> 27775 | D9: =SUMIFS(LIBERACION!$V:$V,LIBERACION!$Y:$Y,$B9,LIBERACION!$B:$B,D$6) -> 0 | E9: =SUMIFS(LIBERACION!$V:$V,LIBERACION!$Y:$Y,$B9,LIBERACION!$B:$B,E$6) -> 26675 | F9: =SUM(C9:E9) -> 54450 | G9: Argentina parada por mantenimiento, TOKIO FLEX 12 MULTICONDUCTOR 3X12:BLANCO,VERDE NEGRO: 30360
B10: 46198 | C10: =SUMIFS(LIBERACION!$V:$V,LIBERACION!$Y:$Y,$B10,LIBERACION!$B:$B,C$6) -> 64050 | D10: =SUMIFS(LIBERACION!$V:$V,LIBERACION!$Y:$Y,$B10,LIBERACION!$B:$B,D$6) -> 0 | E10: =SUMIFS(LIBERACION!$V:$V,LIBERACION!$Y:$Y,$B10,LIBERACION!$B:$B,E$6) -> 18400 | F10: =SUM(C10:E10) -> 82450 | G10: ARGENTINA FABRICA FLEX 8 CC VERDE,BLANCO, NEGRO (15360 mts), TOKIO GEMELO 2X16 PARA BOBINAS DE 500: (36000 mts)
B11: 46199 | C11: =SUMIFS(LIBERACION!$V:$V,LIBERACION!$Y:$Y,$B11,LIBERACION!$B:$B,C$6) -> 57385 | D11: =SUMIFS(LIBERACION!$V:$V,LIBERACION!$Y:$Y,$B11,LIBERACION!$B:$B,D$6) -> 0 | E11: =SUMIFS(LIBERACION!$V:$V,LIBERACION!$Y:$Y,$B11,LIBERACION!$B:$B,E$6) -> 25200 | F11: =SUM(C11:E11) -> 82585 | G11: ARGENTINA FLEX 16 CC4X16; BLANCO, VERDE, NEGRO, ROJO: (20460 mts) TOKIO GEMELO 2X18 BOBINAS PRESENTACION 500: (35000 mts )
E12: TOTAL | F12: =SUM( F7:F11 ) -> 389760
B16: REPORTE LIBERACIÓN PORCENTUAL %
B17: FECHA | C17: TURNO | F17: PORCENTAJE POR DIA
C18: MAÑANA | D18: TARDE | E18: NOCHE
C19: M | D19: T | E19: N
B20: =B7 -> 46195 | C20: =((C7*100)/500000)/100 -> 0.12165 | D20: =((D7*100)/500000)/100 -> 0 | E20: =((E7*100)/500000)/100 -> 0.06 | F20: =SUM(C20:E20) -> 0.18165
B21: =B8 -> 46196 | C21: =((C8*100)/500000)/100 -> 0.0984 | D21: =((D8*100)/500000)/100 -> 0 | E21: =((E8*100)/500000)/100 -> 0.0605 | F21: =SUM(C21:E21) -> 0.1589
B22: =B9 -> 46197 | C22: =((C9*100)/500000)/100 -> 0.05555 | D22: =((D9*100)/500000)/100 -> 0 | E22: =((E9*100)/500000)/100 -> 0.05335 | F22: =SUM(C22:E22) -> 0.1089
B23: =B10 -> 46198 | C23: =((C10*100)/500000)/100 -> 0.1281 | D23: =((D10*100)/500000)/100 -> 0 | E23: =((E10*100)/500000)/100 -> 0.0368 | F23: =SUM(C23:E23) -> 0.1649
B24: =B11 -> 46199 | C24: =((C11*100)/500000)/100 -> 0.11477 | D24: =((D11*100)/500000)/100 -> 0 | E24: =((E11*100)/500000)/100 -> 0.0504 | F24: =SUM(C24:E24) -> 0.16517
E25: TOTAL % | F25: =SUM(F20:F24) -> 0.77952

Sheet SEMANA5
B1: }
B3: REPORTE DE LIBERACIÓN SEMANAL
B4: FECHA | C4: TURNO | F4: METROS POR DIA | G4: OBSERVACIONES
C5: MAÑANA | D5: TARDE | E5: NOCHE
C6: M | D6: T | E6: N
B7: 46202 | C7: =SUMIFS(LIBERACION!$V:$V,LIBERACION!$Y:$Y,$B7,LIBERACION!$B:$B,C$6) -> 76600 | D7: =SUMIFS(LIBERACION!$V:$V,LIBERACION!$Y:$Y,$B7,LIBERACION!$B:$B,D$6) -> 0 | E7: =SUMIFS(LIBERACION!$V:$V,LIBERACION!$Y:$Y,$B7,LIBERACION!$B:$B,E$6) -> 29100 | F7: =SUM(C7:E7) -> 105700
B8: 46203 | C8: =SUMIFS(LIBERACION!$V:$V,LIBERACION!$Y:$Y,$B8,LIBERACION!$B:$B,C$6) -> 36035 | D8: =SUMIFS(LIBERACION!$V:$V,LIBERACION!$Y:$Y,$B8,LIBERACION!$B:$B,D$6) -> 0 | E8: =SUMIFS(LIBERACION!$V:$V,LIBERACION!$Y:$Y,$B8,LIBERACION!$B:$B,E$6) -> 26350 | F8: =SUM(C8:E8) -> 62385 | G8: FABRICACION DE FLEX 12 MULTI COL:BLANCO 60000 MTRS; VERDE 15000 MTRS(TOKIO)
B9: 46204 | C9: =SUMIFS(LIBERACION!$V:$V,LIBERACION!$Y:$Y,$B9,LIBERACION!$B:$B,C$6) -> 43225 | D9: =SUMIFS(LIBERACION!$V:$V,LIBERACION!$Y:$Y,$B9,LIBERACION!$B:$B,D$6) -> 0 | E9: =SUMIFS(LIBERACION!$V:$V,LIBERACION!$Y:$Y,$B9,LIBERACION!$B:$B,E$6) -> 34025 | F9: =SUM(C9:E9) -> 77250 | G9: FABRICACION DE FLEX 12 MULTI COL:NEGRO 60000 MTRS; VERDE 15000 MTRS(TOKIO)
B10: 46205 | C10: =SUMIFS(LIBERACION!$V:$V,LIBERACION!$Y:$Y,$B10,LIBERACION!$B:$B,C$6) -> 60275 | D10: =SUMIFS(LIBERACION!$V:$V,LIBERACION!$Y:$Y,$B10,LIBERACION!$B:$B,D$6) -> 0 | E10: =SUMIFS(LIBERACION!$V:$V,LIBERACION!$Y:$Y,$B10,LIBERACION!$B:$B,E$6) -> 40100 | F10: =SUM(C10:E10) -> 100375
B11: 46206 | C11: 58225 | D11: 0 | E11: 61300 | F11: 119525
E12: TOTAL | F12: =SUM( F7:F11 ) -> 465235
B16: REPORTE LIBERACIÓN PORCENTUAL %
B17: FECHA | C17: TURNO | F17: PORCENTAJE POR DIA
C18: MAÑANA | D18: TARDE | E18: NOCHE
C19: M | D19: T | E19: N
B20: =B7 -> 46202 | C20: =((C7*100)/500000)/100 -> 0.1532 | D20: =((D7*100)/500000)/100 -> 0 | E20: =((E7*100)/500000)/100 -> 0.0582 | F20: =SUM(C20:E20) -> 0.2114
B21: =B8 -> 46203 | C21: =((C8*100)/500000)/100 -> 0.07207 | D21: =((D8*100)/500000)/100 -> 0 | E21: =((E8*100)/500000)/100 -> 0.0527 | F21: =SUM(C21:E21) -> 0.12477
B22: =B9 -> 46204 | C22: =((C9*100)/500000)/100 -> 0.08645 | D22: =((D9*100)/500000)/100 -> 0 | E22: =((E9*100)/500000)/100 -> 0.06805 | F22: =SUM(C22:E22) -> 0.1545
B23: =B10 -> 46205 | C23: =((C10*100)/500000)/100 -> 0.12055 | D23: =((D10*100)/500000)/100 -> 0 | E23: =((E10*100)/500000)/100 -> 0.0802 | F23: =SUM(C23:E23) -> 0.20075
B24: =B11 -> 46206 | C24: =((C11*100)/500000)/100 -> 0.11645 | D24: =((D11*100)/500000)/100 -> 0 | E24: =((E11*100)/500000)/100 -> 0.1226 | F24: =SUM(C24:E24) -> 0.23905
E25: TOTAL % | F25: =SUM(F20:F24) -> 0.93047
